# Error handling

Error handling in Rust is based on the `Result` and `Option` types. The `Result` type is used when an operation can return an error, while the `Option` type represents the possibility of a value being absent. Here are some robust examples that showcase error handling in Rust:

Example 1: Returning a `Result` from a function

```rust
use std::fs::File;
use std::io::Read;


fn read_file_contents(filename: &str) -> Result<String, std::io::Error> {
    let mut file = File::open(filename)?;
    let mut contents = String::new();
    file.read_to_string(&mut contents)?;
    Ok(contents)
}

fn main() {
    let result = read_file_contents("example.txt");
    match result {
        Ok(contents) => println!("File contents: {}", contents),
        Err(error) => println!("Error: {}", error),
    }
}
```

In this example, the `read_file_contents` function attempts to open a file, read its contents, and return them as a `String`. If any operation encounters an error, a `Result` with the appropriate error type (`std::io::Error` in this case) is returned. In the `main` function, we handle the result using a `match` expression, printing the file contents if successful (`Ok`) or the encountered error (`Err`).

Example 2: Propagating errors with the `?` operator
```rust
use std::fs;

fn read_file_contents(filename: &str) -> Result<String, std::io::Error> {
    let contents = fs::read_to_string(filename)?;
    Ok(contents)
}

fn process_file(filename: &str) -> Result<(), Box<dyn std::error::Error>> {
    let contents = read_file_contents(filename)?;
    // Process the file contents
    Ok(())
}

fn main() {
    let result = process_file("example.txt");
    match result {
        Ok(()) => println!("File processed successfully"),
        Err(error) => println!("Error: {}", error),
    }
}
```

In this example, the `read_file_contents` function is similar to the previous example, but it uses the `?` operator to propagate errors automatically. If an error occurs during the `read_to_string` operation, the error is immediately returned from the function. The `process_file` function calls `read_file_contents` and propagates any errors it encounters. The `main` function handles the result, printing a success message or the encountered error.

Example 3: Unwrapping `Option` values
```rust
fn get_first_element(slice: &[i32]) -> Option<i32> {
    if slice.is_empty() {
        None
    } else {
        Some(slice[0])
    }
}

fn main() {
    let numbers = vec![1, 2, 3];
    let first_number = get_first_element(&numbers);
    match first_number {
        Some(number) => println!("First number: {}", number),
        None => println!("No numbers found"),
    }
}
```

In this example, the `get_first_element` function takes a slice of `i32` values and returns an `Option<i32>`. If the slice is empty, it returns `None`, indicating that no element was found. Otherwise, it returns `Some(element)` with the first element of the slice. In the `main` function, we handle the `Option` result using a `match` expression, printing the first number if present (`Some`) or a message indicating no numbers were found (`None`).

These examples showcase various aspects of error handling in Rust, including returning and propagating `Result` values, handling errors with the `

Here is an explanation of error handling in Rust with robust examples:

- **What is error handling?**

Error handling is the process of dealing with errors that occur during the execution of a program. Rust has a number of features for handling errors, including the `Result` enum, the `panic!` macro, and the `Error` trait.

- **The `Result` enum**

The `Result` enum is a special enum that is used to represent the result of a computation that can either be successful or unsuccessful. The `Result` enum has two variants: `Ok` and `Err`. The `Ok` variant contains the successful result, and the `Err` variant contains the error.

- **The `panic!` macro**

The `panic!` macro is used to handle unrecoverable errors. When the `panic!` macro is called, the program will terminate immediately.

- **The `Error` trait**

The `Error` trait is a trait that can be implemented by any type that represents an error. The `Error` trait provides a number of methods for working with errors, such as the `source()` method, which returns the source of the error, and the `description()` method, which returns a description of the error.

- **Examples of error handling**

Here are some examples of error handling in Rust:

```rust
  fn divide(numerator: i32, denominator: i32) -> Result<i32, String> {
      if denominator == 0 {
          return Err("Division by zero");
      } else {
          return Ok(numerator / denominator);
      }
  }
  
  fn main() {
      let result = divide(10, 2);
  
      if let Ok(x) = result {
          println!("The result is {}", x);
      } else {
          println!("Error: {}", result.err().unwrap());
      }
  }
```

In this example, the `divide()` function takes two integers as arguments and returns a `Result`. The `divide()` function returns `Err` if the denominator is 0, and it returns `Ok(x)` if the denominator is not 0, where `x` is the result of the division.

The `main()` function calls the `divide()` function and then checks the result. If the result is `Ok`, the `main()` function prints the result to the console. If the result is `Err`, the `main()` function prints the error message to the console.

- **Conclusion**

Error handling is an important part of any programming language. Rust has a number of features for handling errors, which make it a robust and reliable language.

